<?xml version="1.0" encoding="utf-8"?>
<!-- This URDF was automatically created by SolidWorks to URDF Exporter! Originally created by Stephen Brawner (brawner@gmail.com) 
     Commit Version: 1.6.0-4-g7f85cfe  Build Version: 1.6.7995.38578
     For more information, please see http://wiki.ros.org/sw_urdf_exporter -->
<robot
  name="ax6113final">
  <link
    name="base_footprint">

  </link>
  <link
    name="chassis">
    <inertial>
      <origin
        xyz="-0.0061677633792033 -7.36965152760838E-05 0.086667587274659"
        rpy="0 0 0" />
      <mass
        value="119.2695104108364" />
      <inertia
        ixx="0.26409748280951"
        ixy="0.000400164588261267"
        ixz="0.00147157353940033"
        iyy="0.603892272508937"
        iyz="0.000102408582079296"
        izz="0.822504402380331" />
    </inertial>
    <visual>
      <origin
        xyz="0 0 0"
        rpy="0 0 0" />
      <geometry>
        <mesh
          filename="package://ax6113final/meshes/base_link.STL" />
      </geometry>
      <material
        name="">
        <color
          rgba="0.741176470588235 1 0.741176470588235 1" />
      </material>
    </visual>
    <collision>
      <origin
        xyz="0 0 0"
        rpy="0 0 0" />
      <geometry>
        <mesh
          filename="package://ax6113final/meshes/base_link.STL" />
      </geometry>
    </collision>
  </link>
  <joint
    name="base_link_it"
    type="fixed">
    <origin
      xyz="0 0 0"
      rpy="0 0 0" />
    <parent
      link="base_footprint" />
    <child
      link="chassis" />
    <axis
      xyz="0 0 0" />
  </joint>  
  <link
    name="left_wheel">
    <inertial>
      <origin
        xyz="-1.49880108324396E-15 -1.67921232474555E-15 0.0399999999999999"
        rpy="0 0 0" />
      <mass
        value="1.28203160205244" />
      <inertia
        ixx="0.00231577757345468"
        ixy="-4.31280942310315E-20"
        ixz="1.92674672986061E-30"
        iyy="0.00231577757345468"
        iyz="-1.41023922860637E-23"
        izz="0.00362433959821745" />
    </inertial>
    <visual>
      <origin
        xyz="0 0 0"
        rpy="0 0 0" />
      <geometry>
        <mesh
          filename="package://ax6113final/meshes/left_wheel.STL" />
      </geometry>
      <material
        name="">
        <color
          rgba="0.792156862745098 0.819607843137255 0.933333333333333 1" />
      </material>
    </visual>
    <collision>
      <origin
        xyz="0 0 0"
        rpy="0 0 0" />
      <geometry>
        <mesh
          filename="package://ax6113final/meshes/left_wheel.STL" />
      </geometry>
    </collision>
  </link>
  <joint
    name="wheel_left_joint"
    type="continuous">
    <origin
      xyz="-0.00017343 0.122 -0.025"
      rpy="-1.5708 0 0" />
    <parent
      link="chassis" />
    <child
      link="left_wheel" />
    <axis
      xyz="0 0 1" />

  </joint>
  <link
    name="right_wheel">
    <inertial>
      <origin
        xyz="-1.49880108324396E-15 1.67921232474555E-15 0.04"
        rpy="0 0 0" />
      <mass
        value="1.28203160205243" />
      <inertia
        ixx="0.00231577757345468"
        ixy="-2.39856156124579E-19"
        ixz="3.33907854319744E-20"
        iyy="0.00231577757345468"
        iyz="3.35466292051951E-20"
        izz="0.00362433959821744" />
    </inertial>
    <visual>
      <origin
        xyz="0 0 0"
        rpy="0 0 0" />
      <geometry>
        <mesh
          filename="package://ax6113final/meshes/right_wheel.STL" />
      </geometry>
      <material
        name="">
        <color
          rgba="0.792156862745098 0.819607843137255 0.933333333333333 1" />
      </material>
    </visual>
    <collision>
      <origin
        xyz="0 0 0"
        rpy="0 0 0" />
      <geometry>
        <mesh
          filename="package://ax6113final/meshes/right_wheel.STL" />
      </geometry>
    </collision>
  </link>
  <joint
    name="wheel_right_joint"
    type="continuous">
    <origin
      xyz="-0.00017343 -0.122 -0.025"
      rpy="1.5708 0 0" />
    <parent
      link="chassis" />
    <child
      link="right_wheel" />
    <axis
      xyz="0 0 -1" />

  </joint>
  <link
    name="caster_fl">
    <inertial>
      <origin
        xyz="-9.49507084806456E-05 -1.26961278157367E-08 -0.0220751390633198"
        rpy="0 0 0" />
      <mass
        value="0.050730191615594" />
      <inertia
        ixx="2.13076622270567E-05"
        ixy="-4.77236871564436E-12"
        ixz="-2.15459258559363E-07"
        iyy="2.12936580597202E-05"
        iyz="-3.19013832586914E-11"
        izz="9.21167172451167E-06" />
    </inertial>
    <visual>
      <origin
        xyz="0 0 0"
        rpy="0 0 0" />
      <geometry>
        <mesh
          filename="package://ax6113final/meshes/caster_fl.STL" />
      </geometry>
      <material
        name="">
        <color
          rgba="0.792156862745098 0.819607843137255 0.933333333333333 1" />
      </material>
    </visual>
    <collision>
      <origin
        xyz="0 0 0"
        rpy="0 0 0" />
      <geometry>
        <mesh
          filename="package://ax6113final/meshes/caster_fl.STL" />
      </geometry>
    </collision>
  </link>
  <joint
    name="caster_fl_joint"
    type="continuous">
    <origin
      xyz="0.27024 0.1595 0"
      rpy="0 0 0" />
    <parent
      link="chassis" />
    <child
      link="caster_fl" />
    <axis
      xyz="0 0 -1" />
    <dynamics
      damping="0.01"
      friction="0.5" />
  </joint>
  <link
    name="caster_fl_wheel">
    <inertial>
      <origin
        xyz="0 0 0.0275"
        rpy="0 0 0" />
      <mass
        value="1.17460228082973" />
      <inertia
        ixx="0.000104635302988195"
        ixy="7.06845372568766E-38"
        ixz="-6.13296480894052E-21"
        iyy="0.000104635302988195"
        iyz="-1.83670992315982E-37"
        izz="9.9322531726992E-05" />
    </inertial>
    <visual>
      <origin
        xyz="0 0 0"
        rpy="0 0 0" />
      <geometry>
        <mesh
          filename="package://ax6113final/meshes/caster_fl_wheel.STL" />
      </geometry>
      <material
        name="">
        <color
          rgba="0.792156862745098 0.819607843137255 0.933333333333333 1" />
      </material>
    </visual>
    <collision>
      <origin
        xyz="0 0 0"
        rpy="0 0 0" />
      <geometry>
        <mesh
          filename="package://ax6113final/meshes/caster_fl_wheel.STL" />
      </geometry>
    </collision>
  </link>
  <joint
    name="caster_fl_wheel_joint"
    type="continuous">
    <origin
      xyz="-0.025 -0.0275 -0.067"
      rpy="-1.5708 0 0" />
    <parent
      link="caster_fl" />
    <child
      link="caster_fl_wheel" />
    <axis
      xyz="0 0 -1" />

  </joint>
  <link
    name="caster_fr">
    <inertial>
      <origin
        xyz="-9.49507084806456E-05 -1.26961278296145E-08 -0.0220751390633199"
        rpy="0 0 0" />
      <mass
        value="0.0507301916155941" />
      <inertia
        ixx="2.13076622270568E-05"
        ixy="-4.77236871446618E-12"
        ixz="-2.15459258559358E-07"
        iyy="2.12936580597203E-05"
        iyz="-3.19013832894133E-11"
        izz="9.21167172451168E-06" />
    </inertial>
    <visual>
      <origin
        xyz="0 0 0"
        rpy="0 0 0" />
      <geometry>
        <mesh
          filename="package://ax6113final/meshes/caster_fr.STL" />
      </geometry>
      <material
        name="">
        <color
          rgba="0.792156862745098 0.819607843137255 0.933333333333333 1" />
      </material>
    </visual>
    <collision>
      <origin
        xyz="0 0 0"
        rpy="0 0 0" />
      <geometry>
        <mesh
          filename="package://ax6113final/meshes/caster_fr.STL" />
      </geometry>
    </collision>
  </link>
  <joint
    name="caster_fr_joint"
    type="continuous">
    <origin
      xyz="0.27024 -0.1595 0"
      rpy="0 0 0" />
    <parent
      link="chassis" />
    <child
      link="caster_fr" />
    <axis
      xyz="0 0 1" />
    <dynamics
      damping="0.01"
      friction="0.5" />
  </joint>
  <link
    name="caster_fr_wheel">
    <inertial>
      <origin
        xyz="1.11022302462516E-16 0 0.0275"
        rpy="0 0 0" />
      <mass
        value="1.17460228082973" />
      <inertia
        ixx="0.000104635302988195"
        ixy="-7.06845372568759E-38"
        ixz="3.38010773036404E-21"
        iyy="0.000104635302988195"
        iyz="3.67341984631965E-37"
        izz="9.9322531726992E-05" />
    </inertial>
    <visual>
      <origin
        xyz="0 0 0"
        rpy="0 0 0" />
      <geometry>
        <mesh
          filename="package://ax6113final/meshes/caster_fr_wheel.STL" />
      </geometry>
      <material
        name="">
        <color
          rgba="0.792156862745098 0.819607843137255 0.933333333333333 1" />
      </material>
    </visual>
    <collision>
      <origin
        xyz="0 0 0"
        rpy="0 0 0" />
      <geometry>
        <mesh
          filename="package://ax6113final/meshes/caster_fr_wheel.STL" />
      </geometry>
    </collision>
  </link>
  <joint
    name="caster_fr_wheel_joint"
    type="continuous">
    <origin
      xyz="-0.025 0.0275 -0.067"
      rpy="1.5708 0 0" />
    <parent
      link="caster_fr" />
    <child
      link="caster_fr_wheel" />
    <axis
      xyz="0 0 1" />

  </joint>
  <link
    name="caster_bl">
    <inertial>
      <origin
        xyz="-9.49507084806317E-05 -1.26961278157367E-08 -0.0220751390633199"
        rpy="0 0 0" />
      <mass
        value="0.050730191615594" />
      <inertia
        ixx="2.13076622270567E-05"
        ixy="-4.77236871442357E-12"
        ixz="-2.15459258559362E-07"
        iyy="2.12936580597203E-05"
        iyz="-3.19013832734618E-11"
        izz="9.21167172451167E-06" />
    </inertial>
    <visual>
      <origin
        xyz="0 0 0"
        rpy="0 0 0" />
      <geometry>
        <mesh
          filename="package://ax6113final/meshes/caster_bl.STL" />
      </geometry>
      <material
        name="">
        <color
          rgba="0.792156862745098 0.819607843137255 0.933333333333333 1" />
      </material>
    </visual>
    <collision>
      <origin
        xyz="0 0 0"
        rpy="0 0 0" />
      <geometry>
        <mesh
          filename="package://ax6113final/meshes/caster_bl.STL" />
      </geometry>
    </collision>
  </link>
  <joint
    name="caster_bl_joint"
    type="continuous">
    <origin
      xyz="-0.25726 0.1595 0"
      rpy="0 0 0" />
    <parent
      link="chassis" />
    <child
      link="caster_bl" />
    <axis
      xyz="0 0 -1" />
    <dynamics
      damping="0.01"
      friction="0.5" />
  </joint>
  <link
    name="caster_bl_wheel">
    <inertial>
      <origin
        xyz="0 0 0.0275000000000001"
        rpy="0 0 0" />
      <mass
        value="1.17460228082973" />
      <inertia
        ixx="0.000104635302988195"
        ixy="-2.18320536339829E-22"
        ixz="-3.40426455200137E-21"
        iyy="0.000104635302988195"
        iyz="-2.93213903879748E-23"
        izz="9.9322531726992E-05" />
    </inertial>
    <visual>
      <origin
        xyz="0 0 0"
        rpy="0 0 0" />
      <geometry>
        <mesh
          filename="package://ax6113final/meshes/caster_bl_wheel.STL" />
      </geometry>
      <material
        name="">
        <color
          rgba="0.792156862745098 0.819607843137255 0.933333333333333 1" />
      </material>
    </visual>
    <collision>
      <origin
        xyz="0 0 0"
        rpy="0 0 0" />
      <geometry>
        <mesh
          filename="package://ax6113final/meshes/caster_bl_wheel.STL" />
      </geometry>
    </collision>
  </link>
  <joint
    name="caster_bl_wheel_joint"
    type="continuous">
    <origin
      xyz="-0.025 -0.0275 -0.067"
      rpy="-1.5708 0 0" />
    <parent
      link="caster_bl" />
    <child
      link="caster_bl_wheel" />
    <axis
      xyz="0 0 -1" />

  </joint>
  <link
    name="caster_br">
    <inertial>
      <origin
        xyz="-9.49507084806178E-05 -1.26961278018589E-08 -0.0220751390633198"
        rpy="0 0 0" />
      <mass
        value="0.050730191615594" />
      <inertia
        ixx="2.13076622270566E-05"
        ixy="-4.77236871365657E-12"
        ixz="-2.15459258559352E-07"
        iyy="2.12936580597202E-05"
        iyz="-3.19013832878592E-11"
        izz="9.21167172451169E-06" />
    </inertial>
    <visual>
      <origin
        xyz="0 0 0"
        rpy="0 0 0" />
      <geometry>
        <mesh
          filename="package://ax6113final/meshes/caster_br.STL" />
      </geometry>
      <material
        name="">
        <color
          rgba="0.792156862745098 0.819607843137255 0.933333333333333 1" />
      </material>
    </visual>
    <collision>
      <origin
        xyz="0 0 0"
        rpy="0 0 0" />
      <geometry>
        <mesh
          filename="package://ax6113final/meshes/caster_br.STL" />
      </geometry>
    </collision>
  </link>
  <joint
    name="caster_br_joint"
    type="continuous">
    <origin
      xyz="-0.25726 -0.1595 0"
      rpy="0 0 0" />
    <parent
      link="chassis" />
    <child
      link="caster_br" />
    <axis
      xyz="0 0 -1" />
    <dynamics
      damping="0.01"
      friction="0.5" />
  </joint>
  <link
    name="caster_br_wheel">
    <inertial>
      <origin
        xyz="0 8.67361737988404E-19 0.0274999999999999"
        rpy="0 0 0" />
      <mass
        value="1.17460228082973" />
      <inertia
        ixx="0.000104635302988195"
        ixy="2.50084271861865E-22"
        ixz="3.39768762188313E-21"
        iyy="0.000104635302988195"
        iyz="-1.77704802405951E-23"
        izz="9.9322531726992E-05" />
    </inertial>
    <visual>
      <origin
        xyz="0 0 0"
        rpy="0 0 0" />
      <geometry>
        <mesh
          filename="package://ax6113final/meshes/caster_br_wheel.STL" />
      </geometry>
      <material
        name="">
        <color
          rgba="0.792156862745098 0.819607843137255 0.933333333333333 1" />
      </material>
    </visual>
    <collision>
      <origin
        xyz="0 0 0"
        rpy="0 0 0" />
      <geometry>
        <mesh
          filename="package://ax6113final/meshes/caster_br_wheel.STL" />
      </geometry>
    </collision>
  </link>
  <joint
    name="caster_br_wheel_joint"
    type="continuous">
    <origin
      xyz="-0.025 0.0275 -0.067"
      rpy="1.5708 0 0" />
    <parent
      link="caster_br" />
    <child
      link="caster_br_wheel" />
    <axis
      xyz="0 0 1" />

  </joint>
  <link
    name="cabin">
    <inertial>
      <origin
        xyz="0.1 0.380318965024053 0.0176873782655099"
        rpy="0 0 0" />
      <mass
        value="5.44372411947952" />
      <inertia
        ixx="0.276045180016053"
        ixy="-8.88033322182947E-17"
        ixz="-1.73633908902948E-18"
        iyy="0.0187935661671801"
        iyz="0.000362046000427621"
        izz="0.293672513292604" />
    </inertial>
    <visual>
      <origin
        xyz="0 0 0"
        rpy="0 0 0" />
      <geometry>
        <mesh
          filename="package://ax6113final/meshes/cabin.STL" />
      </geometry>
      <material
        name="">
        <color
          rgba="0.792156862745098 0.819607843137255 0.933333333333333 1" />
      </material>
    </visual>
    <collision>
      <origin
        xyz="0 0 0"
        rpy="0 0 0" />
      <geometry>
        <mesh
          filename="package://ax6113final/meshes/cabin.STL" />
      </geometry>
    </collision>
  </link>
  <joint
    name="cabin_joint"
    type="fixed">
    <origin
      xyz="0.325 0.1 0.183"
      rpy="1.5707963267949 0 -1.5707963267949" />
    <parent
      link="chassis" />
    <child
      link="cabin" />
    <axis
      xyz="0 0 0" />
  </joint>
    <link
    name="lidar">
    <inertial>
      <origin
        xyz="-2.77555756156289E-17 0 -0.005"
        rpy="0 0 0" />
      <mass
        value="0.000785398163397448" />
      <inertia
        ixx="1.14537232162128E-08"
        ixy="0"
        ixz="0"
        iyy="1.14537232162128E-08"
        iyz="0"
        izz="9.8174770424681E-09" />
    </inertial>
    <visual>
      <origin
        xyz="0 0 0"
        rpy="0 0 0" />
      <geometry>
        <mesh
          filename="package://autoxing/meshes/lidar.STL" />
      </geometry>
      <material
        name="">
        <color
          rgba="0.792156862745098 0.819607843137255 0.933333333333333 1" />
      </material>
    </visual>
    <collision>
      <origin
        xyz="0 0 0"
        rpy="0 0 0" />
      <geometry>
        <mesh
          filename="package://autoxing/meshes/lidar.STL" />
      </geometry>
    </collision>
  </link>
  <joint
    name="lidar_joint"
    type="fixed">
    <origin
      xyz="0.00671416680612409 0.00186793926091405 0.138"
      rpy="0 0 0" />
    <parent
      link="chassis" />
    <child
      link="lidar" />
    <axis
      xyz="0 0 0" />
  </joint>
   <!-- hokuyo -->
  <gazebo reference="lidar">
    <sensor type="ray" name="sensor">
      <pose>0 0 0 0 0 0</pose>
      <visualize>false</visualize>
      <update_rate>40</update_rate>
      <ray>
        <scan>
          <horizontal>
            <samples>720</samples>
            <resolution>1</resolution>
            <min_angle>-1.570796</min_angle>
            <max_angle>1.570796</max_angle> <!-- 1.570796 4.712388-->
          </horizontal>
        </scan>
        <range>
          <min>0.10</min>
          <max>30.0</max>
          <resolution>0.01</resolution>
        </range>
        <noise>
          <type>gaussian</type>
          <!-- Noise parameters based on published spec for Hokuyo laser
               achieving "+-30mm" accuracy at range < 10m.  A mean of 0.0m and
               stddev of 0.01m will put 99.7% of samples within 0.03m of the true
               reading. -->
          <mean>0.0</mean>
          <stddev>0.01</stddev>
        </noise>
      </ray>
      
      <plugin name="hokuyo_node" filename="libgazebo_ros_laser.so">
        <topicName>/laser/scan</topicName>
        <frameName>lidar</frameName>
      </plugin> 
    </sensor>
  </gazebo>
    <!--adding color-->
     <gazebo reference="chassis">
  	<material>Gazebo/Turquoise </material>
  </gazebo>

  <gazebo reference="left_wheel">
  	<mu1>200.0</mu1>
  	<mu2>200.0</mu2>
  	<kp>10000000</kp>
  	<kd>1.0</kd>
  	<material>Gazebo/FlatBlack</material>
  </gazebo>
   <gazebo reference="right_wheel">
  	<mu1>200.0</mu1>
  	<mu2>200.0</mu2>
  	<kp>10000000</kp>
  	<kd>1.0</kd>   
  	<material>Gazebo/FlatBlack</material>
  </gazebo>

   <gazebo reference="caster_fl_wheel">
  	<mu1>0.01</mu1>
  	<mu2>0.01</mu2>
  	<kp>10000000</kp>
  	<kd>1.0</kd>   
  	<material>Gazebo/FlatBlack</material>
  </gazebo>
   <gazebo reference="caster_fr_wheel">
  	<mu1>0.01</mu1>
  	<mu2>0.01</mu2>
  	<kp>10000000</kp>
  	<kd>1.0</kd>   
  	<material>Gazebo/FlatBlack</material>
  </gazebo>
   <gazebo reference="caster_bl_wheel">
  	<mu1>0.01</mu1>
  	<mu2>0.01</mu2>
  	<kp>10000000</kp>
  	<kd>1.0</kd>   
  	<material>Gazebo/FlatBlack</material>
  </gazebo>
   <gazebo reference="caster_br_wheel">
    <mu1>0.01</mu1>
  	<mu2>0.01</mu2>
  	<kp>10000000</kp>
  	<kd>1.0</kd> 
  	<material>Gazebo/FlatBlack</material>
  </gazebo>
   <!-- adding diff drive -->
   <gazebo>
     <plugin name="diff_drive_controller" filename="libgazebo_ros_diff_drive.so">
        <legacyMode>false</legacyMode>
        <alwaysOn>true</alwaysOn>
        <updateRate>50</updateRate>
        <leftJoint>wheel_left_joint</leftJoint>
        <rightJoint>wheel_right_joint</rightJoint>
        <wheelSeparation>0.445208</wheelSeparation>
        <wheelDiameter>0.16</wheelDiameter>
        <wheelTorque>10</wheelTorque>
        <publishTf>1</publishTf>
        <odometryFrame>odom</odometryFrame>
        <commandTopic>cmd_vel</commandTopic>
        <odometryTopic>odom</odometryTopic>
        <robotBaseFrame>base_footprint</robotBaseFrame>
        <wheelAcceleration>2.8</wheelAcceleration>
        <publishWheelJointState>true</publishWheelJointState>
        <publishWheelTF>false</publishWheelTF>
        <odometrySource>odom</odometrySource>
        <rosDebugLevel>Debug</rosDebugLevel>
      </plugin>
    </gazebo> 
    
   <transmission name="left_wheel_trans">
    <type>transmission_interface/SimpleTransmission</type>
    <joint name="wheel_left_joint">
      <hardwareInterface>hardware_interface/VelocityJointInterface</hardwareInterface>
    </joint>
    <actuator name="left_wheel_motor">
      <hardwareInterface>hardware_interface/VelocityJointInterface</hardwareInterface>
      <mechanicalReduction>1</mechanicalReduction>
    </actuator>
  </transmission>
  <transmission name="right_wheel_trans">
    <type>transmission_interface/SimpleTransmission</type>
    <joint name="wheel_right_joint">
      <hardwareInterface>hardware_interface/VelocityJointInterface</hardwareInterface>
    </joint>
    <actuator name="right_wheel_motor">
      <hardwareInterface>hardware_interface/VelocityJointInterface</hardwareInterface>
      <mechanicalReduction>1</mechanicalReduction>
    </actuator>
  </transmission>      
     <gazebo>
    <plugin filename="libgazebo_ros_p3d.so" name="p3d_base_controller">
      <alwaysOn>true</alwaysOn>
      <updateRate>50.0</updateRate>
      <bodyName>base_footprint</bodyName>
      <topicName>base_pose_ground_truth</topicName>
      <gaussianNoise>0.01</gaussianNoise>
      <frameName>map</frameName>
      <xyzOffsets>0 0 0</xyzOffsets>
      <rpyOffsets>0 0 0</rpyOffsets>
    </plugin>
  </gazebo>
  <gazebo>
    <plugin filename="libgazebo_ros_control.so" name="gazebo_ros_control">
      <controlPeriod>0.001</controlPeriod>
      <legacyModeNS>false</legacyModeNS>
    </plugin>
  </gazebo>    

      <transmission name="trans_casterhub_front_left_joint">
        <type>transmission_interface/SimpleTransmission</type>
        <joint name="caster_fl_joint">
            <hardwareInterface>hardware_interface/EffortJointInterface</hardwareInterface>
        </joint>
        <actuator name="casterhub_front_left_joint_motor">
            <hardwareInterface>hardware_interface/EffortJointInterface</hardwareInterface>
            <mechanicalReduction>1</mechanicalReduction>
        </actuator>
    </transmission>
    <transmission name="trans_wheel_lf_joint">
        <type>transmission_interface/SimpleTransmission</type>
        <joint name="caster_fl_wheel_joint">
            <hardwareInterface>hardware_interface/EffortJointInterface</hardwareInterface>
        </joint>
        <actuator name="wheel_lf_joint_motor">
            <hardwareInterface>hardware_interface/EffortJointInterface</hardwareInterface>
            <mechanicalReduction>1</mechanicalReduction>
        </actuator>
    </transmission>
    <transmission name="trans_casterhub_front_right_joint">
        <type>transmission_interface/SimpleTransmission</type>
        <joint name="caster_fr_joint">
            <hardwareInterface>hardware_interface/EffortJointInterface</hardwareInterface>
        </joint>
        <actuator name="casterhub_front_right_joint_motor">
            <hardwareInterface>hardware_interface/EffortJointInterface</hardwareInterface>
            <mechanicalReduction>1</mechanicalReduction>
        </actuator>
    </transmission>
    <transmission name="trans_wheel_rf_joint">
        <type>transmission_interface/SimpleTransmission</type>
        <joint name="caster_fr_wheel_joint">
            <hardwareInterface>hardware_interface/EffortJointInterface</hardwareInterface>
        </joint>
        <actuator name="wheel_rf_joint_motor">
            <hardwareInterface>hardware_interface/EffortJointInterface</hardwareInterface>
            <mechanicalReduction>1</mechanicalReduction>
        </actuator>
    </transmission>
    <transmission name="trans_casterhub_back_left_joint">
        <type>transmission_interface/SimpleTransmission</type>
        <joint name="caster_bl_joint">
            <hardwareInterface>hardware_interface/EffortJointInterface</hardwareInterface>
        </joint>
        <actuator name="casterhub_back_left_joint_motor">
            <hardwareInterface>hardware_interface/EffortJointInterface</hardwareInterface>
            <mechanicalReduction>1</mechanicalReduction>
        </actuator>
    </transmission>
    <transmission name="trans_wheel_lb_joint">
        <type>transmission_interface/SimpleTransmission</type>
        <joint name="caster_bl_wheel_joint">
            <hardwareInterface>hardware_interface/EffortJointInterface</hardwareInterface>
        </joint>
        <actuator name="wheel_lb_joint_motor">
            <hardwareInterface>hardware_interface/EffortJointInterface</hardwareInterface>
            <mechanicalReduction>1</mechanicalReduction>
        </actuator>
    </transmission>
    <transmission name="trans_casterhub_back_right_joint">
        <type>transmission_interface/SimpleTransmission</type>
        <joint name="caster_br_joint">
            <hardwareInterface>hardware_interface/EffortJointInterface</hardwareInterface>
        </joint>
        <actuator name="casterhub_back_right_joint_motor">
            <hardwareInterface>hardware_interface/EffortJointInterface</hardwareInterface>
            <mechanicalReduction>1</mechanicalReduction>
        </actuator>
    </transmission>
    <transmission name="trans_wheel_rb_joint">
        <type>transmission_interface/SimpleTransmission</type>
        <joint name="caster_br_wheel_joint">
            <hardwareInterface>hardware_interface/EffortJointInterface</hardwareInterface>
        </joint>
        <actuator name="wheel_rb_joint_motor">
            <hardwareInterface>hardware_interface/EffortJointInterface</hardwareInterface>
            <mechanicalReduction>1</mechanicalReduction>
        </actuator>
    </transmission> 
 
</robot>
